Workbook
Name Meafyen_offset: [1]הגדרות!$A$16:$B$21
Name Senario_1: [1]תרחישים!#REF!
Name Senario_10: [1]תרחישים!$B$21:$F$27
Name Senario_11: [1]תרחישים!#REF!
Name Senario_12: [1]תרחישים!$N$12:$R$18
Name Senario_13: [1]תרחישים!#REF!
Name Senario_14: [1]תרחישים!$H$21:$L$27
Name Senario_15: [1]תרחישים!$N$21:$R$27
Name Senario_18: [1]תרחישים!#REF!
Name Senario_19: [1]תרחישים!#REF!
Name Senario_2: [1]תרחישים!$H$3:$L$9
Name Senario_3: [1]תרחישים!#REF!
Name Senario_4: [1]תרחישים!$B$3:$F$9
Name Senario_5: [1]תרחישים!$H$12:$L$18
Name Senario_6: [1]תרחישים!$N$3:$R$9
Name Senario_7: [1]תרחישים!$B$12:$F$18
Name Senario_8: [1]תרחישים!#REF!
Name Senario_9: [1]תרחישים!#REF!
Name Senario_Name_1: [1]תרחישים!#REF!
Name Senario_Name_10: [1]תרחישים!$B$20
Name Senario_Name_11: [1]תרחישים!#REF!
Name Senario_Name_12: [1]תרחישים!$N$11
Name Senario_Name_13: [1]תרחישים!#REF!
Name Senario_Name_14: [1]תרחישים!$H$20
Name Senario_Name_15: [1]תרחישים!$N$20
Name Senario_Name_16: [1]תרחישים!$B$29
Name Senario_Name_17: [1]תרחישים!$H$29
Name Senario_Name_18: [1]תרחישים!#REF!
Name Senario_Name_19: [1]תרחישים!#REF!
Name Senario_Name_2: [1]תרחישים!$H$2
Name Senario_Name_20: [1]תרחישים!$H$38
Name Senario_Name_21: [1]תרחישים!$N$29
Name Senario_Name_3: [1]תרחישים!#REF!
Name Senario_Name_4: [1]תרחישים!$B$2
Name Senario_Name_5: [1]תרחישים!$H$11
Name Senario_Name_6: [1]תרחישים!$N$2
Name Senario_Name_7: [1]תרחישים!$B$11
Name Senario_Name_8: [1]תרחישים!#REF!
Name Senario_Name_9: [1]תרחישים!#REF!
Name Threat_Influance: [1]הגדרות!$G$3:$H$8
Name Threat_Name_1: '[1]גורמי איום'!$A$1
Name Threat_Name_2: '[1]גורמי איום'!$G$1
Name Threat_Name_3: '[1]גורמי איום'!$M$1
Name Threat_Name_4: '[1]גורמי איום'!$A$14
Name Threat_Name_5: '[1]גורמי איום'!$G$14
Name Threat_Name_6: '[1]גורמי איום'!$M$14
Name Threat_Name_7: '[1]גורמי איום'!$A$27
Name Threat_Name_8: '[1]גורמי איום'!$G$27
Name Threat_Name_9: '[1]גורמי איום'!$M$27
Name ThreatActors: [1]הגדרות!$M$3:$N$11
Name ציון: [1]הגדרות!$D$3:$D$7

Sheet שלב ראשון - כללי
B1: כללי
B9: שלב ראשון: כללי רשמו את שמות המשתתפים בתרגיל ואת החברה שבחרתם. בחרו חברה הקרובה ללבכם שיש לכם יכולת להעריך סיכונים עבורה. (אין חובה לבחור חברה שאתם עובדים או עבדתם בה אבל החברה צריכה להיות אמיתית).
B12: שם חברה:
B14: אתר
B17: שמות סטודנטים: | D17: שם סטודנט/ית | I17: תפקיד בחברה
I18: מנכ"ל/ית
I19: מנהל/ת אבטחת מידע
I20: מנהל/ת הגנת פרטיות
I21: סוקר/ת חיצוני/ת
I22: סוקר/ת חיצוני/ת

Sheet שלב שני - זיהוי נכסים אסטרטגיים
B1: נכסים אסטרטגיים
B9: שלב שני: זיהוי נכסים אסטרטגיים רשום את כל הנכסים האסטרטגיים של הארגון. זכור לחשוב בגדול ולא בקטן, מהו נכס אסטרטגי של של הארגון שבחרת? כמנהל אבטחת מידע אתה צריך את הנכסים האסטרטגיים כדי לנתח איומים פוטנציאליים, הערכה של הסבירות והתוצאה של כל איום, ומשם סיכונים רלוונטיים. 1 = לא מהותי, 5 = מהותי : נא להשתמש בכל מספר פעם אחת בעמודה
B11: נכס | G11: רמת חשיבות הנכס (1-5) | J11: ההסתברות לפגיעה בנכסים אלו בהתרחש אירוע מהותי (1-5)
B12: הכנס שם של נכס 1
B13: הכנס שם של נכס 2
B14: הכנס שם של נכס 3
B15: הכנס שם של נכס 4
B16: הכנס שם של נכס 5
B17: הכנס שם של נכס 6
B18: הכנס שם של נכס 7
B19: הכנס שם של נכס 8
B23: דוגמא: חברת סלקום
B24: נכס | G24: רמת חשיבות הנכס (1-5) | J24: ההסתברות לפגיעה בנכסים אלו בהתרחש אירוע מהותי (1-5)
B25: מוניטין | G25: 2 | J25: 4
B26: מוצרי תקשורת | G26: 1 | J26: 1
B27: נתונים ומידע | G27: 3 | J27: 2
B28: ידע אנושי | G28: 4 | J28: 3

Sheet שלב שלישי - איומים מרכזיים
B1: זהו 5 איומים מרכזיים
B3: שלב שלישי: זיהוי איומים מרכזיים כדי לזהות את האיומים המרכזיים לנכסי הארגון, עליכם להבין את המהות והתפקוד של כל נכס אסטרטגי בארגון. לדוגמה, מוניטין הארגון הוא קריטי לשמירת לקוחות וקשרים עסקיים, ומידע רגיש יכול לכלול נתוני לקוחות ומסמכים פנימיים חשובים. לאחר מכן צרו איום הרלוונטי לנכס האסטרטגי. 1= לא מהותי, 5 = מהותי
B5: איום | G5: הסבר | L5: משקל | M5: סולם ערכים | P5: ציון (1-5)
B6: 1 | L6: 0.25 | M6: הכנס טקסט לרמה 1 | P6: 1 | T6: =M6 -> הכנס טקסט לרמה 1 | U6: =B6 -> 1 | V6: =L6 -> 0.25
M7: הכנס טקסט לרמה 2 | P7: 2 | T7: =M7 -> הכנס טקסט לרמה 2 | U7: =B11 -> 2 | V7: =L11 -> 0.25
M8: הכנס טקסט לרמה 3 | P8: 3 | T8: =M8 -> הכנס טקסט לרמה 3 | U8: =B16 -> 3 | V8: =L16 -> 0.2
M9: הכנס טקסט לרמה 4 | P9: 4 | T9: =M9 -> הכנס טקסט לרמה 4 | U9: =B21 -> 4 | V9: =L21 -> 0.15
M10: הכנס טקסט לרמה 5 | P10: 5 | T10: =M10 -> הכנס טקסט לרמה 5 | U10: =B26 -> 5 | V10: =L26 -> 0.15
B11: 2 | L11: 0.25 | M11: הכנס טקסט לרמה 1 | P11: 1 | T11: =M11 -> הכנס טקסט לרמה 1
M12: הכנס טקסט לרמה 2 | P12: 2 | T12: =M12 -> הכנס טקסט לרמה 2
M13: הכנס טקסט לרמה 3 | P13: 3 | T13: =M13 -> הכנס טקסט לרמה 3
M14: הכנס טקסט לרמה 4 | P14: 4 | T14: =M14 -> הכנס טקסט לרמה 4
M15: הכנס טקסט לרמה 5 | P15: 5 | T15: =M15 -> הכנס טקסט לרמה 5
B16: 3 | L16: 0.2 | M16: הכנס טקסט לרמה 1 | P16: 1 | T16: =M16 -> הכנס טקסט לרמה 1
M17: הכנס טקסט לרמה 2 | P17: 2 | T17: =M17 -> הכנס טקסט לרמה 2
M18: הכנס טקסט לרמה 3 | P18: 3 | T18: =M18 -> הכנס טקסט לרמה 3
M19: הכנס טקסט לרמה 4 | P19: 4 | T19: =M19 -> הכנס טקסט לרמה 4
M20: הכנס טקסט לרמה 5 | P20: 5 | T20: =M20 -> הכנס טקסט לרמה 5
B21: 4 | L21: 0.15 | M21: הכנס טקסט לרמה 1 | P21: 1 | T21: =M21 -> הכנס טקסט לרמה 1
M22: הכנס טקסט לרמה 2 | P22: 2 | T22: =M22 -> הכנס טקסט לרמה 2
M23: הכנס טקסט לרמה 3 | P23: 3 | T23: =M23 -> הכנס טקסט לרמה 3
M24: הכנס טקסט לרמה 4 | P24: 4 | T24: =M24 -> הכנס טקסט לרמה 4
M25: הכנס טקסט לרמה 5 | P25: 5 | T25: =M25 -> הכנס טקסט לרמה 5
B26: 5 | L26: 0.15 | M26: הכנס טקסט לרמה 1 | P26: 1 | T26: =M26 -> הכנס טקסט לרמה 1
M27: הכנס טקסט לרמה 2 | P27: 2 | T27: =M27 -> הכנס טקסט לרמה 2
M28: הכנס טקסט לרמה 3 | P28: 3 | T28: =M28 -> הכנס טקסט לרמה 3
M29: הכנס טקסט לרמה 4 | P29: 4 | T29: =M29 -> הכנס טקסט לרמה 4
M30: הכנס טקסט לרמה 5 | P30: 5 | T30: =M30 -> הכנס טקסט לרמה 5
L31: =SUM(L6:L30) -> 1
B35: דוגמא: חברת סלקום
B36: איום | G36: הסבר | L36: משקל (אחוז) | M36: סולם ערכים | P36: ציון (1-5)
B37: נזק למידע | G37: נזק למידע של לקוחות הארגון (פגיעה בשלמות המידע או בזמינות המידע) | L37: 0.25 | M37: אין נזק | P37: 1
M38: נזק מועט | P38: 2
M39: נזק ברמה בינונית | P39: 3
M40: נזק ברמה גבוהה | P40: 4
M41: נזק מהותי | P41: 5

Sheet שלב רביעי - גורמי איום
B1: מהם גורמי האיום המרכזיים לארגון ומה היכולות שלהם?
B4: מאפיין | C4: סולם ערכים | D4: ציון | E4: משקל
B5: צורת ההתארגנות | C5: פרט בודד | D5: 1 | E5: 0.2 | I5: =C5 -> פרט בודד
C6: התארגנות של פרטים בודדים | D6: 2 | I6: =C6 -> התארגנות של פרטים בודדים
C7: ארגון בודד | D7: 3 | I7: =C7 -> ארגון בודד
C8: התארגנות של מספר ארגונים | D8: 4 | I8: =C8 -> התארגנות של מספר ארגונים
C9: רמת מדינה/מעצמה | D9: 5 | I9: =C9 -> רמת מדינה/מעצמה
B10: מטרת התקיפה | C10: פרסום עצמי | D10: 1 | E10: 0.25 | I10: =C10 -> פרסום עצמי
C11: איסוף מודיעין | D11: 2 | I11: =C11 -> איסוף מודיעין
C12: רווח כספי | D12: 3 | I12: =C12 -> רווח כספי
C13: פגיעה בהתנהלות השוטפת | D13: 4 | I13: =C13 -> פגיעה בהתנהלות השוטפת
C14: פגיעה בתשתיות/אזרחים | D14: 5 | I14: =C14 -> פגיעה בתשתיות/אזרחים
B15: המניע לתקיפה | C15: סקרנות ושעמום | D15: 1 | E15: 0.05 | I15: =C15 -> סקרנות ושעמום
C16: קידום אג'נדה | D16: 2 | I16: =C16 -> קידום אג'נדה
C17: האדרת התוקף | D17: 3 | I17: =C17 -> האדרת התוקף
C18: ריגול תעשייתי | D18: 4 | I18: =C18 -> ריגול תעשייתי
C19: פיננסי | D19: 5 | I19: =C19 -> פיננסי
B20: ידע וניסיון | C20: אין ידע מוקדם | D20: 1 | E20: 0.15 | I20: =C20 -> אין ידע מוקדם
C21: ידע ברמה נמוכה-בינונית | D21: 2 | I21: =C21 -> ידע ברמה נמוכה-בינונית
C22: ידע ברמה בינונית | D22: 3 | I22: =C22 -> ידע ברמה בינונית
C23: ידע ברמה בינונית-גבוהה | D23: 4 | I23: =C23 -> ידע ברמה בינונית-גבוהה
C24: ידע ברמה גבוהה | D24: 5 | I24: =C24 -> ידע ברמה גבוהה
B25: משאבים | C25: אין משאבים ייעודיים | D25: 1 | E25: 0.15 | I25: =C25 -> אין משאבים ייעודיים
C26: משאבים מוגבלים | D26: 2 | I26: =C26 -> משאבים מוגבלים
C27: כמות משאבים בינונית | D27: 3 | I27: =C27 -> כמות משאבים בינונית
C28: משאבים רבים | D28: 4 | I28: =C28 -> משאבים רבים
C29: משאבים בלתי מוגבלים | D29: 5 | I29: =C29 -> משאבים בלתי מוגבלים
B30: מורכבות תקיפה | C30: Script מוכן | D30: 1 | E30: 0.1 | I30: =C30 -> Script מוכן
C31: נוזקות ידועות | D31: 2 | I31: =C31 -> נוזקות ידועות
C32: Script בפיתוח עצמי | D32: 3 | I32: =C32 -> Script בפיתוח עצמי
C33: נוזקות בפיתוח עצמי | D33: 4 | I33: =C33 -> נוזקות בפיתוח עצמי
C34: כלי האקינג מורכב | D34: 5 | I34: =C34 -> כלי האקינג מורכב
B35: חשיפה לארגון | C35: אין חשיפה מוקדמת | D35: 1 | E35: 0.1 | I35: =C35 -> אין חשיפה מוקדמת
C36: אין חשיפה, אך יש היכרות עם הסביבה הטכנולוגית | D36: 2 | I36: =C36 -> אין חשיפה, אך יש היכרות עם הסביבה הטכנולוגית
C37: אין חשיפה, אך יש זמינות של מומחי תוכן | D37: 3 | I37: =C37 -> אין חשיפה, אך יש זמינות של מומחי תוכן
C38: חשיפה חלקית למשאבים מוגבלים | D38: 4 | I38: =C38 -> חשיפה חלקית למשאבים מוגבלים
C39: חשיפה מלאה ויכולת גישה מלאה | D39: 5 | I39: =C39 -> חשיפה מלאה ויכולת גישה מלאה
E56: =SUM(E5:E39) -> 1
B58: התוקפים:
B60: דוגמא: גורם פנימי בעל הרשאות גבוהות | C60: מאפיין | D60: משקל | E60: ציון | F60: סולם ערכים | G60: תוצאה
...

Sheet שלב חמש - תרחישי איום מרכזיים
B1: מהם תרחישי האיום המרכזיים לארגון?
B4: דוגמא: חברת סלקום
B6: התקפת כופרה | F6: =SUM(F8:F12) -> 2.95
B7: איום (נלקח משלב 3) | C7: ערכים רלבנטיים | D7: ציון | E7: משקל
B8: נזק למידע | C8: נזק מהותי למידע | D8: 5 | E8: 0.2 | F8: =D8*E8 -> 1
B9: דלף מידע | C9: גניבה של מידע לא מהותי | D9: 2 | E9: 0.15 | F9: =D9*E9 -> 0.3
B10: השבתת פעילות | C10: השבתה של חלק מהותי מהפעילות הארגונית | D10: 5 | E10: 0.25 | F10: =D10*E10 -> 1.25
B11: פגיעה בידע אנושי | C11: איו פגיעה בידע אנושי | D11: 1 | E11: 0.1 | F11: =D11*E11 -> 0.1
B12: פגיה במוניטין | C12: פגיעה בינונית במוניטין | D12: 1 | E12: 0.3 | F12: =D12*E12 -> 0.3
B15: החברה שלנו:
H16: =B17 -> XX1
B17: XX1 | F17: =SUM(F19:F23) -> 2.45 | H17: =B25 -> XX2
B18: איום (נלקח משלב 3) | C18: ערכים רלבנטיים | D18: ציון | E18: משקל | H18: =B33 -> XX3
B19: ='שלב שלישי - איומים מרכזיים'!U6 -> 1 | C19: =VLOOKUP(D19,'שלב שלישי - איומים מרכזיים'!$P$6:$T$10,5) -> הכנס טקסט לרמה 3 | D19: 3 | E19: ='שלב שלישי - איומים מרכזיים'!V6 -> 0.25 | F19: =D19*E19 -> 0.75 | H19: =B41 -> XX4
B20: ='שלב שלישי - איומים מרכזיים'!U7 -> 2 | C20: =VLOOKUP(D20,'שלב שלישי - איומים מרכזיים'!$P$11:$T$15,5) -> הכנס טקסט לרמה 1 | D20: 1 | E20: ='שלב שלישי - איומים מרכזיים'!V7 -> 0.25 | F20: =D20*E20 -> 0.25
B21: ='שלב שלישי - איומים מרכזיים'!U8 -> 3 | C21: =VLOOKUP(D21,'שלב שלישי - איומים מרכזיים'!$P$16:$T$20,5) -> הכנס טקסט לרמה 2 | D21: 2 | E21: ='שלב שלישי - איומים מרכזיים'!V8 -> 0.2 | F21: =D21*E21 -> 0.4
B22: ='שלב שלישי - איומים מרכזיים'!U9 -> 4 | C22: =VLOOKUP(D22,'שלב שלישי - איומים מרכזיים'!$P$21:$T$25,5) -> הכנס טקסט לרמה 3 | D22: 3 | E22: ='שלב שלישי - איומים מרכזיים'!V9 -> 0.15 | F22: =D22*E22 -> 0.45
B23: ='שלב שלישי - איומים מרכזיים'!U10 -> 5 | C23: =VLOOKUP(D23,'שלב שלישי - איומים מרכזיים'!$P$26:$T$30,5) -> הכנס טקסט לרמה 4 | D23: 4 | E23: ='שלב שלישי - איומים מרכזיים'!V10 -> 0.15 | F23: =D23*E23 -> 0.6
B25: XX2 | F25: =SUM(F27:F31) -> 0
B26: איום (נלקח משלב 3) | C26: ערכים רלבנטיים | D26: ציון | E26: משקל
B27: ='שלב שלישי - איומים מרכזיים'!U6 -> 1 | C27: =VLOOKUP(D27,'שלב שלישי - איומים מרכזיים'!$P$6:$T$10,5) -> #N/A | E27: ='שלב שלישי - איומים מרכזיים'!V6 -> 0.25 | F27: =D27*E27 -> 0
B28: ='שלב שלישי - איומים מרכזיים'!U7 -> 2 | C28: =VLOOKUP(D28,'שלב שלישי - איומים מרכזיים'!$P$11:$T$15,5) -> #N/A | E28: ='שלב שלישי - איומים מרכזיים'!V7 -> 0.25 | F28: =D28*E28 -> 0
B29: ='שלב שלישי - איומים מרכזיים'!U8 -> 3 | C29: =VLOOKUP(D29,'שלב שלישי - איומים מרכזיים'!$P$16:$T$20,5) -> #N/A | E29: ='שלב שלישי - איומים מרכזיים'!V8 -> 0.2 | F29: =D29*E29 -> 0
B30: ='שלב שלישי - איומים מרכזיים'!U9 -> 4 | C30: =VLOOKUP(D30,'שלב שלישי - איומים מרכזיים'!$P$21:$T$25,5) -> #N/A | E30: ='שלב שלישי - איומים מרכזיים'!V9 -> 0.15 | F30: =D30*E30 -> 0
B31: ='שלב שלישי - איומים מרכזיים'!U10 -> 5 | C31: =VLOOKUP(D31,'שלב שלישי - איומים מרכזיים'!$P$26:$T$30,5) -> #N/A | E31: ='שלב שלישי - איומים מרכזיים'!V10 -> 0.15 | F31: =D31*E31 -> 0
B33: XX3 | F33: =SUM(F35:F39) -> 0
B34: איום (נלקח משלב 3) | C34: ערכים רלבנטיים | D34: ציון | E34: משקל
B35: ='שלב שלישי - איומים מרכזיים'!U6 -> 1 | C35: =VLOOKUP(D35,'שלב שלישי - איומים מרכזיים'!$P$6:$T$10,5) -> #N/A | E35: ='שלב שלישי - איומים מרכזיים'!V6 -> 0.25 | F35: =D35*E35 -> 0
B36: ='שלב שלישי - איומים מרכזיים'!U7 -> 2 | C36: =VLOOKUP(D36,'שלב שלישי - איומים מרכזיים'!$P$11:$T$15,5) -> #N/A | E36: ='שלב שלישי - איומים מרכזיים'!V7 -> 0.25 | F36: =D36*E36 -> 0
B37: ='שלב שלישי - איומים מרכזיים'!U8 -> 3 | C37: =VLOOKUP(D37,'שלב שלישי - איומים מרכזיים'!$P$16:$T$20,5) -> #N/A | E37: ='שלב שלישי - איומים מרכזיים'!V8 -> 0.2 | F37: =D37*E37 -> 0
B38: ='שלב שלישי - איומים מרכזיים'!U9 -> 4 | C38: =VLOOKUP(D38,'שלב שלישי - איומים מרכזיים'!$P$21:$T$25,5) -> #N/A | E38: ='שלב שלישי - איומים מרכזיים'!V9 -> 0.15 | F38: =D38*E38 -> 0
B39: ='שלב שלישי - איומים מרכזיים'!U10 -> 5 | C39: =VLOOKUP(D39,'שלב שלישי - איומים מרכזיים'!$P$26:$T$30,5) -> #N/A | E39: ='שלב שלישי - איומים מרכזיים'!V10 -> 0.15 | F39: =D39*E39 -> 0
B41: XX4 | F41: =SUM(F43:F47) -> 0
B42: איום (נלקח משלב 3) | C42: ערכים רלבנטיים | D42: ציון | E42: משקל
B43: ='שלב שלישי - איומים מרכזיים'!U6 -> 1 | C43: =VLOOKUP(D43,'שלב שלישי - איומים מרכזיים'!$P$6:$T$10,5) -> #N/A | E43: ='שלב שלישי - איומים מרכזיים'!V6 -> 0.25 | F43: =D43*E43 -> 0
B44: ='שלב שלישי - איומים מרכזיים'!U7 -> 2 | C44: =VLOOKUP(D44,'שלב שלישי - איומים מרכזיים'!$P$11:$T$15,5) -> #N/A | E44: ='שלב שלישי - איומים מרכזיים'!V7 -> 0.25 | F44: =D44*E44 -> 0
B45: ='שלב שלישי - איומים מרכזיים'!U8 -> 3 | C45: =VLOOKUP(D45,'שלב שלישי - איומים מרכזיים'!$P$16:$T$20,5) -> #N/A | E45: ='שלב שלישי - איומים מרכזיים'!V8 -> 0.2 | F45: =D45*E45 -> 0
B46: ='שלב שלישי - איומים מרכזיים'!U9 -> 4 | C46: =VLOOKUP(D46,'שלב שלישי - איומים מרכזיים'!$P$21:$T$25,5) -> #N/A | E46: ='שלב שלישי - איומים מרכזיים'!V9 -> 0.15 | F46: =D46*E46 -> 0
B47: ='שלב שלישי - איומים מרכזיים'!U10 -> 5 | C47: =VLOOKUP(D47,'שלב שלישי - איומים מרכזיים'!$P$26:$T$30,5) -> #N/A | E47: ='שלב שלישי - איומים מרכזיים'!V10 -> 0.15 | F47: =D47*E47 -> 0

Sheet שלב שש - ניתוח סיכונים
B1: כתבו 5 סיכונים
B6: איום | C6: רמת נזק שורשי | D6: סיכון - צריך להיות הסבר מה יקרה - מה הסיכון! | E6: נכסים באיום | F6: הסתברות (1-5) | G6: רמת סיכון נוכחי | H6: הציעו בקרות | I6: נזק לאחר בקרות | J6: הסתברות (1-5) לאחר בקרות | K6: רמת סיכון לאחר תוכנית בקרות
B7: התקפת כופרה | C7: ='שלב חמש - תרחישי איום מרכזיים'!F6 -> 2.95 | D7: אובדן מידע הנגרם עקב מתקפת כופר כתוצאה מהנדסה חברתית | E7: נתונים ומידע | F7: 3 | G7: =F7*C7 -> 8.85 | H7: תירגולי פישינג הכשרת עובדים | I7: 2.95 | J7: 2 | K7: =J7*I7 -> 5.9
B8: ='שלב חמש - תרחישי איום מרכזיים'!H16 -> XX1 | C8: ='שלב חמש - תרחישי איום מרכזיים'!F17 -> 2.45 | G8: =F8*C8 -> 0 | K8: =J8*I8 -> 0
B9: ='שלב חמש - תרחישי איום מרכזיים'!H17 -> XX2 | C9: ='שלב חמש - תרחישי איום מרכזיים'!F25 -> 0 | G9: =F9*C9 -> 0 | K9: =J9*I9 -> 0
B10: ='שלב חמש - תרחישי איום מרכזיים'!H18 -> XX3 | C10: ='שלב חמש - תרחישי איום מרכזיים'!F33 -> 0 | G10: =F10*C10 -> 0 | K10: =J10*I10 -> 0
B11: ='שלב חמש - תרחישי איום מרכזיים'!H19 -> XX4 | C11: ='שלב חמש - תרחישי איום מרכזיים'!F41 -> 0 | G11: =F11*C11 -> 0 | K11: =J11*I11 -> 0
